Workbook
Name Alte_observatii: 'QAF628'!$B$67
Name cable_cap: 'QAF628'!$D$11
Name Cam1_mapata_NICM: 'QAF628'!$M$51
Name Cam2_mapata_NICM: 'QAF628'!$M$52
Name Cam3_mapata_NICM: 'QAF628'!$M$53
Name Cam4_mapata_NICM: 'QAF628'!$M$54
Name Cauza: 'QAF628'!$C$23
Name data_finalizare_optic: 'QAF628'!$F$21
Name data_localizare_incident: 'QAF628'!$F$20
Name data_solicitare_interv: 'QAF628'!$F$18
Name data_sosire_in_zona_incident: 'QAF628'!$F$19
Name Descriere_incident: 'QAF628'!$C$25
Name Descriere_remediere: 'QAF628'!$C$29
Name distanta_fault1: 'QAF628'!$P$15
Name distanta_fault2: 'QAF628'!$Q$15
Name EVR: 'QAF628'!$D$15
Name execute_contractor: 'QAF628'!$K$9
Name fisiere_atasate: 'QAF628'!$K$56
Name J1_mapata_NICM: 'QAF628'!$L$41
Name J1_to_A: 'QAF628'!$P$41
Name J1_to_B: 'QAF628'!$R$41
Name J2_mapata_NICM: 'QAF628'!$L$42
Name J2_to_A: 'QAF628'!$P$42
Name J2_to_B: 'QAF628'!$R$42
Name J3_mapata_NICM: 'QAF628'!$L$43
Name J3_to_A: 'QAF628'!$P$43
Name J3_to_B: 'QAF628'!$R$43
Name J4_mapata_NICM: 'QAF628'!$L$44
Name J4_to_A: 'QAF628'!$P$44
Name J4_to_B: 'QAF628'!$R$44
Name Judet: 'QAF628'!$H$14
Name link_C1: 'QAF628'!$G$51
Name link_C2: 'QAF628'!$G$52
Name link_C3: 'QAF628'!$G$53
Name link_C4: 'QAF628'!$G$54
Name link_incident1: 'QAF628'!$C$35
Name link_incident2: 'QAF628'!$C$39
Name link_J1: 'QAF628'!$G$41
Name link_J2: 'QAF628'!$G$42
Name link_J3: 'QAF628'!$G$43
Name link_J4: 'QAF628'!$G$44
Name locatie_masuratoare1: 'QAF628'!$P$14
Name locatie_masuratoare2: 'QAF628'!$Q$14
Name masuratori_finale_fo_masurate: 'QAF628'!$I$56
Name masuratori_finale_ODF: 'QAF628'!$E$56
Name masuratori_finale_siteA: 'QAF628'!$C$56
Name masuratori_finale_toSiteB: 'QAF628'!$G$56
Name nume_c1_noua: 'QAF628'!$N$51
Name nume_c2_noua: 'QAF628'!$N$52
Name nume_c3_noua: 'QAF628'!$N$53
Name nume_c4_noua: 'QAF628'!$N$54
Name nume_j1_noua: 'QAF628'!$C$46
Name nume_j2_noua: 'QAF628'!$C$47
Name nume_j3_noua: 'QAF628'!$C$48
Name nume_j4_noua: 'QAF628'!$C$49
Name Nume_tronson: 'QAF628'!$D$7
Name Obs: 'QAF628'!$A$59
Name ora_finalizare_optic: 'QAF628'!$G$21
Name ora_localizare_incident: 'QAF628'!$G$20
Name ora_solicitare_interv: 'QAF628'!$G$18

Sheet QAF628
A1: AABAABBBAABB | B1: ="Raport Mentenanta Fibra Optica - "&MID(qaf_code,8,4) -> Raport Mentenanta Fibra Optica - BAAB | P1: TD
A5: Informatii sectiune : | C5: Cod site A : | J5: Cod site B :
D6: =MID(D5,1,2) | E6: =MID(D5,3,4) | K6: =MID(K5,1,2)
A7: Denumirea tronsonului FO : | P7: =COUNTA(site_code_A,topologie_tronson,cable_cap,Tip,execute_contractor) -> 1
A9: Topologie tronson : | J9: CONTRACTOR executant: | K9: Proconect
C11: Capacitate cablu : | E11: fibre | H11: Tip traseu: | K11: =IF(P7=0,"",IF(P7<>5,"Completeaza campurile obligatorii din aceasta sectiune","")) -> Completeaza campurile obligatorii din aceasta sectiune
A13: Informatii interventie : | F13: SLA | H13: Judet | P13: Mas. 1 | Q13: Mas. 2
C14: Tip interventie : | O14: Site/locatie masuratoare :
C15: Numar ticket : | O15: Distanta fault/atenuare fata de locul masuratorii : | R15: km
C16: Localitatea de plecare echipa :
C17: Zi | D17: Luna | E17: An | G17: Ora | I17: =YEAR(TODAY()) -> 2026 | J17: =COUNTA(Tip_interv,EVR,Plecare,Cauza,C34,E34,site_code_A) -> 1
B18: Data solicitare interventie : | F18: =CONCATENATE(IF(C18<10,"0"&C18,C18),"/",IF(D18<10,"0"&D18,D18),"/",E18) -> 0/0/ | P18: =IF(J17=0,"",IF(J17<>7,"Celulele portocalii din aceasta sectiune sunt obligatorii !!! Celelalte se vor completa in functie de necesitati.","")) -> Celulele portocalii din aceasta sectiune sunt obligatorii !!! Celelalte se vor completa in functie de necesitati.
B19: Data sosire ST in zona : | F19: =CONCATENATE(IF(C19<10,"0"&C19,C19),"/",IF(D19<10,"0"&D19,D19),"/",E19) -> 0/0/
B20: Data localizare incident : | F20: =CONCATENATE(IF(C20<10,"0"&C20,C20),"/",IF(D20<10,"0"&D20,D20),"/",E20) -> 0/0/
B21: Data finalizare interventie : | F21: =CONCATENATE(IF(C21<10,"0"&C21,C21),"/",IF(D21<10,"0"&D21,D21),"/",E21) -> 0/0/
B23: Cauza incident : | C23: Lucrari infrastructura-Lucrari efectuate de companiile nationale
B26: Descriere incident :
B30: Descriere remediere :
C33: LAT | E33: LONG | K33: LEGENDA
B34: Coordonate incident1 : | K34: Coordonatele se completeaza aici doar in doua moduri, vezi celulele cu galben.
B35: Link catre Google Maps : | C35: =IF(AND(ISBLANK(C34),ISBLANK(E34)),"",IF('Nu sterge'!W1="LAT ok, LONG ok",HYPERLINK(CONCATENATE("http://maps.google.com/maps?q=",'Nu sterge'!V1)),'Nu sterge'!W1)) | K35: Celulele albastre se vor copia la coordonatele incidentelor/jonctiunilor.
L36: grade | M36: minute | N36: secunde | R36: copy/paste
C37: LAT | E37: LONG | K37: LAT | L37: 46 | M37: 14 | N37: 16.27 | O37: =VALUE(LEFT(L37+VALUE(M37/60)+VALUE(N37/3600),9)) -> 46.237852 | Q37: =L37&"⁰ "&M37&"' "&N37&"""" -> 46⁰ 14' 16.27" | R37: =O37 -> 46.237852
B38: Coordonate incident2 : | K38: LONG | L38: 27 | M38: 37 | N38: 53.21 | O38: =VALUE(LEFT(L38+VALUE(M38/60)+VALUE(N38/3600),9)) -> 27.631447 | Q38: =L38&"⁰ "&M38&"' "&N38&"""" -> 27⁰ 37' 53.21" | R38: =O38 -> 27.631447
B39: Link catre Google Maps : | C39: =IF(AND(ISBLANK(C38),ISBLANK(E38)),"",IF('Nu sterge'!W4="LAT ok, LONG ok",HYPERLINK(CONCATENATE("http://maps.google.com/maps?q=",'Nu sterge'!V4)),'Nu sterge'!W4))
A40: Materiale : | G40: Link google jonctiuni | L40: Mapata in NICM | M40: Tip jonctiune | O40: Rezerva | P40: spre siteA | Q40: Rezerva | R40: spre siteB
B41: Coordonate jonctiune J1: | G41: =IF(AND(ISBLANK(C41),ISBLANK(E41)),"",IF('Nu sterge'!W7="LAT ok, LONG ok",HYPERLINK(CONCATENATE("http://maps.google.com/maps?q=",'Nu sterge'!V7)),'Nu sterge'!W7))
B42: Coordonate jonctiune J2: | G42: =IF(AND(ISBLANK(C42),ISBLANK(E42)),"",IF('Nu sterge'!W10="LAT ok, LONG ok",HYPERLINK(CONCATENATE("http://maps.google.com/maps?q=",'Nu sterge'!V10)),'Nu sterge'!W10))
B43: Coordonate jonctiune J3: | G43: =IF(AND(ISBLANK(C43),ISBLANK(E43)),"",IF('Nu sterge'!W13="LAT ok, LONG ok",HYPERLINK(CONCATENATE("http://maps.google.com/maps?q=",'Nu sterge'!V13)),'Nu sterge'!W13))
B44: Coordonate jonctiune J4: | G44: =IF(AND(ISBLANK(C44),ISBLANK(E44)),"",IF('Nu sterge'!W16="LAT ok, LONG ok",HYPERLINK(CONCATENATE("http://maps.google.com/maps?q=",'Nu sterge'!V16)),'Nu sterge'!W16))
B46: Denumire NICM jonctiune J1:
B47: Denumire NICM jonctiune J2:
B48: Denumire NICM jonctiune J3:
B49: Denumire NICM jonctiune J4:
M50: Mapata in NICM | N50: Denumire in NICM
B51: Coordonate camereta C1 : | G51: =IF(AND(ISBLANK(C51),ISBLANK(E51)),"",IF('Nu sterge'!W19="LAT ok, LONG ok",HYPERLINK(CONCATENATE("http://maps.google.com/maps?q=",'Nu sterge'!V19)),'Nu sterge'!W19))
B52: Coordonate camereta C2 : | G52: =IF(AND(ISBLANK(C52),ISBLANK(E52)),"",IF('Nu sterge'!W22="LAT ok, LONG ok",HYPERLINK(CONCATENATE("http://maps.google.com/maps?q=",'Nu sterge'!V22)),'Nu sterge'!W22))
B53: Coordonate camereta C3 : | G53: =IF(AND(ISBLANK(C53),ISBLANK(E53)),"",IF('Nu sterge'!W25="LAT ok, LONG ok",HYPERLINK(CONCATENATE("http://maps.google.com/maps?q=",'Nu sterge'!V25)),'Nu sterge'!W25))
B54: Coordonate camereta C4 : | G54: =IF(AND(ISBLANK(C54),ISBLANK(E54)),"",IF('Nu sterge'!W28="LAT ok, LONG ok",HYPERLINK(CONCATENATE("http://maps.google.com/maps?q=",'Nu sterge'!V28)),'Nu sterge'!W28))
C55: Site A | E55: ODF | G55: catre site B | I55: Fibre masurate | K55: Fisiere
...

Sheet ORO Optical Materials
A1: Item code | B1: Item description | C1: Unit | D1: Quantity
A2: 10276926 | B2: ODB - with 8 duplex mating adaptors+Splitter 1:8 | C2: buc
A3: 60074834 | B3: FAUA|FT|K0D1E0 96 (8x12) G.657A2 | C3: ml
A4: 60074835 | B4: FAUA|K0D1E0 144 (12x12) G.657A2 | C4: ml
A5: 60088565 | B5: FADI|FT|K0D1E0 24(4x6) G657A2 | C5: ml
A6: 60088566 | B6: FADI|FT|K0D1E0|48(4x12) G657A2 | C6: ml
A7: 60088567 | B7: FADI|FT|K0D1E0|12(2x6) G657A2 | C7: ml
A8: 60097285 | B8: FUMD LT E0 96 8 (12G.657A1) - TDS10129-R14 | C8: ml
A9: 60107610 | B9: FADS LT K0E0 24(6NZD+18G652D)-TC08382 | C9: ml
A10: 60101654 | B10: FADS|LT|K0EO|24 4x6 G.652D -TC07302-en | C10: ml
A11: 60107782 | B11: FADS|LT|K0E0|12 2(6 G652D)-TC08382 | C11: ml
A12: 60107823 | B12: FADS LT K0E0 48(6G652D)-TC08382-en | C12: ml
A13: 60107854 | B13: FADS|LT|K0E0|24 4(6 G652D)-TC08382 | C13: ml
A14: 60098618 | B14: FVUA|FT|K0M1 12 1(12G.657A2 200)-TC06871-en | C14: ml
A15: CMJ-F-C-CCCC-X-Y-N | B15: CMJ SE2.2 9-11OVAL 4XCIRC7-20 | C15: buc
A16: UMJ-F-C-CCCC-X-Y-N | B16: UMJ SE2.2 9-11OVAL 4XCIRC7-20 | C16: buc
A17: SC/APC 10DB | B17: Atenuator SC/APC 10DB | C17: buc
A18: SC/APC 2DB | B18: Atenuator SC/APC 2DB | C18: buc
A19: SC/APC 4DB | B19: Atenuator SC/APC 4DB | C19: buc
A20: SC/APC 6DB | B20: Atenuator SC/APC 6DB | C20: buc
A21: T0PL0119RO | B21: POLE 8M R1 GRAY DT 160 DB 310 | C21: buc
A22: T0PL0138RO | B22: POLE 7M L GRAY DT 160MM DB 230 | C22: buc
A23: XKTSC00050 | B23: SPLICE PROTECTOR - 2.2mm x 45 (PACK 12) | C23: buc
A24: XSPSC00472 | B24: 1x4 PLC Bare Fibers 4x4x40 | C24: buc
A25: XSPSC00473 | B25: Compact splitter-PLC-1X8-A2-PG | C25: buc
A26: XSPSC00478 | B26: Compact-PLC-1X8-00SCA-A2-PG | C26: buc
... A30: XSRSC00747 | B30: 48 ports SC/APC ODFs - pigtails | C30: buc

Sheet Materials
A1: No. | B1: ORO Item code | C1: Item description | D1: Unit | E1: Quantity
A2: 1 | B2: MST0001 | C2: Patch 10m E 2000/APC-SC/APC, SM, SX | D2: pcs
A3: 2 | B3: MST0002 | C3: Patch 10m LC/APC-SC/APC, SM, SX | D3: pcs
A4: 3 | B4: MST0003 | C4: Patch 10m LC/PC-SC/APC, SM, SX | D4: pcs
A5: 4 | B5: MST0004 | C5: Patch 10m SC/APC-SC/APC, SM, SX | D5: pcs
A6: 5 | B6: MST0005 | C6: Patch 10m SC/PC-SC/APC, SM, SX, G.657A | D6: pcs
A7: 6 | B7: MST0006 | C7: Patch 15m E 2000/APC-LC/APC, SM, SX | D7: pcs
A8: 7 | B8: MST0007 | C8: Patch 15m E 2000/APC-SC/APC, SM, SX | D8: pcs
A9: 8 | B9: MST0008 | C9: Patch 20m E 2000/APC-LC/APC, SM, SX | D9: pcs
A10: 9 | B10: MST0009 | C10: Patch 20m E 2000/APC-SC/APC, SM, SX | D10: pcs
A11: 10 | B11: MST0010 | C11: Patch 3m E 2000/APC-E 2000/APC, SM, DX | D11: pcs
A12: 11 | B12: MST0011 | C12: Patch 3m E 2000/APC-E 2000/APC, SM, SX | D12: pcs
A13: 12 | B13: MST0012 | C13: Patch 3m E 2000-SC SM, DX | D13: pcs
... A92: 91 | B92: MST0089 | C92: Rubber band-3M - material | D92: pcs

Sheet Services
A1: No. | B1: Item Description | C1: Category | D1: Unit | E1: Quantity | F1: =IF(G1=TRUE,"","Se poate efectua doar o interventie. Se completeaza 1 doar intr-una dintre celulele galbene ") | G1: =IFERROR(IF(E4+E5+E6+E7+E8+E9+E10<=1, TRUE, FALSE),FALSE) -> TRUE
A2: 1 | B2: On Site FO Measurements for FO Incident Diagnose | C2: FO | D2: intervention | F2: On site measurements: local measurement required in order to identify the location of the event; performed only when remote measurements are not available
A3: 2 | B3: Continuous Follow Up Infra Optical Fiber | C3: FO | D3: per km | F3: Optical fiber infrastructure professional assessment and reporting services following QAF. Service and transport to be condiered together with Preventive Maint Item and any of the Corrective Maintenance Corrective items (SP1 FOA to SP7 FOU). Scope is covering 20% yearly of Aerial park, visual inspection performed during the Preventive Maint and/or Corrective maintenance intervention and for the Underground park, visual inspection performed during the Preventive and/or Corrective maintenance intervention 1k (on the left/right from the intervention point), as per SoW & Technical Specifications
A4: 3 | B4: Adv. Corrective Maint.(FO) | C4: SP1 FO | D4: intervention | F4: Complete services On-site repairs only (ODF, patch); all services included, except those considered as Specific Works (listed under); The Specific Works items (10-23) will be used in the BoQ on top of Service Package (1-7) if required. General requirements applicable to all Service Packages (SP 1 to 7), depending to the infrastructure caracteristics (on site intervention, aerial or underground): fault identification (including required digging), cable installation and preparation, all fibers splicing, closure box - closing, sealing, installation-, handhole installation (including handhole required digging), transport, tests, measurements intervention report, material BoQ, inventory database updates. The other Specific Works will be used in the BoQ seprately if necessary. Only final remediation will be considered for Service Package ticket validation.
A5: 4 | B5: Adv. Corrective Maint.(FO) | C5: SP2 FOA | D5: intervention | F5: Complete services Aerial repairs (no new cable required); all services included, except those considered as Specific Works (listed under); The Specific Works items (10-23) will be used in the BoQ on top of Service Package (1-7) if required. General requirements applicable to all Service Packages (SP 1 to7), depending to the infrastructure caracteristics (on site intervention, aerial or underground): fault identification (including required digging), cable installation and preparation, all fibers splicing, closure box - closing, sealing, installation-, handhole installation (including handhole required digging), transport, tests, measurements intervention report, material BoQ, inventory database updates. The other Specific Works will be used in the BoQ seprately if necessary. Only final remediation will be considered for Service Package ticket validation.
A6: 5 | B6: Adv. Corrective Maint.(FO) | C6: SP3 FOA | D6: intervention | F6: Complete services Aerial repairs (<200m new cable required); all services included, except those considered as Specific Works (listed under); The Specific Works items (10-23) will be used in the BoQ on top of Service Package (1-7) if required. General requirements applicable to all Service Packages (SP 1 to 7), depending to the infrastructure caracteristics (on site intervention, aerial or underground): fault identification (including required digging), cable installation and preparation, all fibers splicing, closure box - closing, sealing, installation-, handhole installation (including handhole required digging), transport, tests, measurements intervention report, material BoQ, inventory database updates. The other Specific Works will be used in the BoQ seprately if necessary. Only final remediation will be considered for Service Package ticket validation.
A7: 6 | B7: Adv. Corrective Maint.(FO) | C7: CR4 FOA | D7: intervention | F7: Complete services Aerial, Capital repairs (>200m new cable required); all services included, except those considered as Specific Works (listed under); The Specific Works items (10-23) will be used in the BoQ on top of Service Package (1-7) if required. General requirements applicable to all Service Packages (SP 1 to 7), depending to the infrastructure caracteristics (on site intervention, aerial or underground): fault identification (including required digging), cable installation and preparation, all fibers splicing, closure box - closing, sealing, installation-, handhole installation (including handhole required digging), transport, tests, measurements intervention report, material BoQ, inventory database updates. The other Specific Works will be used in the BoQ seprately if necessary. Only final remediation will be considered for Service Package ticket validation.
A8: 7 | B8: Adv. Corrective Maint.(FO) | C8: SP5 FOU | D8: intervention | F8: Complete services Underground repairs (up to max 100m cable required); all services included, except those considered as Specific Works (listed under); The Specific Works items (10-23) will be used in the BoQ on top of Service Package (1-7) if required. General requirements applicable to all Service Packages (SP 1 to 7), depending to the infrastructure caracteristics (on site intervention, aerial or underground): fault identification (including required digging), cable installation and preparation, all fibers splicing, closure box - closing, sealing, installation-, handhole installation (including handhole required digging), transport, tests, measurements intervention report, material BoQ, inventory database updates. The other Specific Works will be used in the BoQ seprately if necessary. Only final remediation will be considered for Service Package ticket validation.
A9: 8 | B9: Adv. Corrective Maint.(FO) | C9: CR6 FOU | D9: intervention | F9: Complete services Underground, Capital repairs (100m to 300m new cable required); all services included, except those considered as Specific Works (listed under); The Specific Works items (10-23) will be used in the BoQ on top of Service Package (1-7) if required. General requirements applicable to all Service Packages (SP 1 to 7), depending to the infrastructure caracteristics (on site intervention, aerial or underground): fault identification (including required digging), cable installation and preparation, all fibers splicing, closure box - closing, sealing, installation-, handhole installation (including handhole required digging), transport, tests, measurements intervention report, material BoQ, inventory database updates. The other Specific Works will be used in the BoQ seprately if necessary. Only final remediation will be considered for Service Package ticket validation.
A10: 9 | B10: Adv. Corrective Maint.(FO) | C10: CR7 FOU | D10: intervention | F10: Complete services Underground, Capital repairs (>300m cable required); all services included, except those considered as Specific Works (listed under); The Specific Works items (10-23) will be used in the BoQ on top of Service Package (1-7) if required. General requirements applicable to all Service Packages (SP 1 to 7), depending to the infrastructure caracteristics (on site intervention, aerial or underground): fault identification (including required digging), cable installation and preparation, all fibers splicing, closure box - closing, sealing, installation-, handhole installation (including handhole required digging), transport, tests, measurements intervention report, material BoQ, inventory database updates. The other Specific Works will be used in the BoQ seprately if necessary. Only final remediation will be considered for Service Package ticket validation.
A11: 10 | B11: Adv. Corrective Maint.(FO) | C11: Directed drilling | D11: m | F11: Forare orizontala dirijata (servicii complete, transport, consumabile) ; Guided horizontal drilling (full services + transport); incl. transport, consumables
A12: 11 | B12: Adv. Corrective Maint.(FO) | C12: Unguided drilling | D12: m | F12: Forare orizontala nedirijata (servicii complete, transport, consumabile); Unguided horizontal drilling (full services + transport); incl. transport, consumables
A13: 12 | B13: Adv. Corrective Maint.(FO) | C13: Pole replacement wood, composite | D13: pcs | F13: Inlocuire stalp de lemn/compozit incl preluarea stalpului existent (servicii complete, transport, consumabile); Replacement of wooden / composite pole incl. removal of existing pole (full services + transport); incl. transport, consumables
... A25: 24 | B25: Adv. Corrective Maint.(FO) | C25: Small civil works intervention | D25: intervention | F25: Lucrari civile minore pentru stalpi din lemn/compozit, infrastructura subterana, camine de vizitare, cutii de tragere; Minor civil works for wooden/composite poles, underground infrastructure, manholes, pulling boxes

Sheet Name_manager
A1: Nume | B1: Locatie | C1: Continut | D1: ROW | E1: Zona | F1: ERROR | L1: =L2&","&L3&","&L4&","&L5&","&L6&","&L7&","&L8 -> ,,,,,,
A2: qaf_code | B2: ='QAF628'!$A$1 | C2: =INDIRECT(A2) -> AABAABBBAABB | D2: =VALUE(MID(B2,FIND("$",B2,FIND("$",B2,1)+1)+1,3)) -> 1 | E2: antet | F2: =ISERR(C2) -> FALSE | J2: =COUNTIFS(E:E,K2,F:F,TRUE) -> 0 | K2: antet | L2: =IF(J2=1, K2, "")
A3: site_code_A | B3: ='QAF628'!$D$5 | C3: =INDIRECT(A3) -> 0 | D3: =VALUE(MID(B3,FIND("$",B3,FIND("$",B3,1)+1)+1,3)) -> 5 | E3: antet | F3: =ISERR(C3) -> FALSE | J3: =COUNTIFS(E:E,K3,F:F,TRUE) -> 0 | K3: Info interv.: partea initiala | L3: =IF(J3=1, K3, "")
A4: site_code_B | B4: ='QAF628'!$K$5 | C4: =INDIRECT(A4) -> 0 | D4: =VALUE(MID(B4,FIND("$",B4,FIND("$",B4,1)+1)+1,3)) -> 5 | E4: antet | F4: =ISERR(C4) -> FALSE | J4: =COUNTIFS(E:E,K4,F:F,TRUE) -> 0 | K4: Info interv.: zona coordonate incident | L4: =IF(J4=1, K4, "")
A5: Nume_tronson | B5: ='QAF628'!$D$7 | C5: =INDIRECT(A5) -> 0 | D5: =VALUE(MID(B5,FIND("$",B5,FIND("$",B5,1)+1)+1,3)) -> 7 | E5: antet | F5: =ISERR(C5) -> FALSE | J5: =COUNTIFS(E:E,K5,F:F,TRUE) -> 0 | K5: Info interv.: partea finala | L5: =IF(J5=1, K5, "")
A6: execute_contractor | B6: ='QAF628'!$K$9 | C6: =INDIRECT(A6) -> Proconect | D6: =VALUE(MID(B6,FIND("$",B6,FIND("$",B6,1)+1)+1,3)) -> 9 | E6: antet | F6: =ISERR(C6) -> FALSE | J6: =COUNTIFS(E:E,K6,F:F,TRUE) -> 0 | K6: Observatii | L6: =IF(J6=1, K6, "")
A7: topologie_tronson | B7: ='QAF628'!$D$9 | C7: =INDIRECT(A7) -> 0 | D7: =VALUE(MID(B7,FIND("$",B7,FIND("$",B7,1)+1)+1,3)) -> 9 | E7: antet | F7: =ISERR(C7) -> FALSE | J7: =COUNTIFS(E:E,K7,F:F,TRUE) -> 0 | K7: Urmarirea constructiei | L7: =IF(J7=1, K7, "")
A8: cable_cap | B8: ='QAF628'!$D$11 | C8: =INDIRECT(A8) -> 0 | D8: =VALUE(MID(B8,FIND("$",B8,FIND("$",B8,1)+1)+1,3)) -> 11 | E8: antet | F8: =ISERR(C8) -> FALSE | J8: =COUNTIFS(E:E,K8,F:F,TRUE) -> 0 | K8: Verificare finala | L8: =IF(J8=1, K8, "")
A9: Tip | B9: ='QAF628'!$I$11 | C9: =INDIRECT(A9) -> 0 | D9: =VALUE(MID(B9,FIND("$",B9,FIND("$",B9,1)+1)+1,3)) -> 11 | E9: antet | F9: =ISERR(C9) -> FALSE | J9: =COUNTIFS(E:E,K9,F:F,TRUE) -> 0 | L9: =IF(J9=1, K9, "")
A10: Judet | B10: ='QAF628'!$H$14 | C10: =INDIRECT(A10) -> 0 | D10: =VALUE(MID(B10,FIND("$",B10,FIND("$",B10,1)+1)+1,3)) -> 14 | E10: Info interv.: partea initiala | F10: =ISERR(C10) -> FALSE | J10: =COUNTIFS(E:E,K10,F:F,TRUE) -> 0 | L10: =IF(J10=1, K10, "")
A11: locatie_masuratoare1 | B11: ='QAF628'!$P$14 | C11: =INDIRECT(A11) -> 0 | D11: =VALUE(MID(B11,FIND("$",B11,FIND("$",B11,1)+1)+1,3)) -> 14 | E11: Info interv.: partea initiala | F11: =ISERR(C11) -> FALSE | J11: =COUNTIFS(E:E,K11,F:F,TRUE) -> 0 | L11: =IF(J11=1, K11, "")
A12: locatie_masuratoare2 | B12: ='QAF628'!$Q$14 | C12: =INDIRECT(A12) -> 0 | D12: =VALUE(MID(B12,FIND("$",B12,FIND("$",B12,1)+1)+1,3)) -> 14 | E12: Info interv.: partea initiala | F12: =ISERR(C12) -> FALSE | J12: =COUNTIFS(E:E,K12,F:F,TRUE) -> 0 | L12: =IF(J12=1, K12, "")
A13: SLA | B13: ='QAF628'!$F$14 | C13: =INDIRECT(A13) -> 0 | D13: =VALUE(MID(B13,FIND("$",B13,FIND("$",B13,1)+1)+1,3)) -> 14 | E13: Info interv.: partea initiala | F13: =ISERR(C13) -> FALSE | J13: =SUM(J2:J12) -> 0
A14: Tip_interv | B14: ='QAF628'!$D$14 | C14: =INDIRECT(A14) -> 0 | D14: =VALUE(MID(B14,FIND("$",B14,FIND("$",B14,1)+1)+1,3)) -> 14 | E14: Info interv.: partea initiala | F14: =ISERR(C14) -> FALSE
A15: distanta_fault1 | B15: ='QAF628'!$P$15 | C15: =INDIRECT(A15) -> 0 | D15: =VALUE(MID(B15,FIND("$",B15,FIND("$",B15,1)+1)+1,3)) -> 15 | E15: Info interv.: partea initiala | F15: =ISERR(C15) -> FALSE
A16: distanta_fault2 | B16: ='QAF628'!$Q$15 | C16: =INDIRECT(A16) -> 0 | D16: =VALUE(MID(B16,FIND("$",B16,FIND("$",B16,1)+1)+1,3)) -> 15 | E16: Info interv.: partea initiala | F16: =ISERR(C16) -> FALSE
A17: EVR | B17: ='QAF628'!$D$15 | C17: =INDIRECT(A17) -> 0 | D17: =VALUE(MID(B17,FIND("$",B17,FIND("$",B17,1)+1)+1,3)) -> 15 | E17: Info interv.: partea initiala | F17: =ISERR(C17) -> FALSE
A18: Plecare | B18: ='QAF628'!$D$16 | C18: =INDIRECT(A18) -> 0 | D18: =VALUE(MID(B18,FIND("$",B18,FIND("$",B18,1)+1)+1,3)) -> 16 | E18: Info interv.: partea initiala | F18: =ISERR(C18) -> FALSE
A19: data_solicitare_interv | B19: ='QAF628'!$F$18 | C19: =INDIRECT(A19) -> 0/0/ | D19: =VALUE(MID(B19,FIND("$",B19,FIND("$",B19,1)+1)+1,3)) -> 18 | E19: Info interv.: partea initiala | F19: =ISERR(C19) -> FALSE
A20: ora_solicitare_interv | B20: ='QAF628'!$G$18 | C20: =INDIRECT(A20) -> 0 | D20: =VALUE(MID(B20,FIND("$",B20,FIND("$",B20,1)+1)+1,3)) -> 18 | E20: Info interv.: partea initiala | F20: =ISERR(C20) -> FALSE
A21: data_sosire_in_zona_incident | B21: ='QAF628'!$F$19 | C21: =INDIRECT(A21) -> 0/0/ | D21: =VALUE(MID(B21,FIND("$",B21,FIND("$",B21,1)+1)+1,3)) -> 19 | E21: Info interv.: partea initiala | F21: =ISERR(C21) -> FALSE
A22: ora_sosire_in_zona_incident | B22: ='QAF628'!$G$19 | C22: =INDIRECT(A22) -> 0 | D22: =VALUE(MID(B22,FIND("$",B22,FIND("$",B22,1)+1)+1,3)) -> 19 | E22: Info interv.: partea initiala | F22: =ISERR(C22) -> FALSE
A23: data_localizare_incident | B23: ='QAF628'!$F$20 | C23: =INDIRECT(A23) -> 0/0/ | D23: =VALUE(MID(B23,FIND("$",B23,FIND("$",B23,1)+1)+1,3)) -> 20 | E23: Info interv.: partea initiala | F23: =ISERR(C23) -> FALSE
A24: ora_localizare_incident | B24: ='QAF628'!$G$20 | C24: =INDIRECT(A24) -> 0 | D24: =VALUE(MID(B24,FIND("$",B24,FIND("$",B24,1)+1)+1,3)) -> 20 | E24: Info interv.: partea initiala | F24: =ISERR(C24) -> FALSE
A25: data_finalizare_optic | B25: ='QAF628'!$F$21 | C25: =INDIRECT(A25) -> 0/0/ | D25: =VALUE(MID(B25,FIND("$",B25,FIND("$",B25,1)+1)+1,3)) -> 21 | E25: Info interv.: partea initiala | F25: =ISERR(C25) -> FALSE
... A85: validate_date | B85: ='QAF628'!$F$79 | C85: =INDIRECT(A85) -> 0/0/ | D85: =VALUE(MID(B85,FIND("$",B85,FIND("$",B85,1)+1)+1,3)) -> 79 | E85: Verificare finala | F85: =ISERR(C85) -> FALSE

Sheet Nu sterge
A1: Accident-Orice tip de accident (masina,etc.) | G1: Judet | I1: ='QAF628'!C34 -> 0 | J1: ='QAF628'!E34 -> 0 | K1: =VALUE(LEFT(I1,2)) -> 0 | L1: =VALUE(MID(I1,FIND("'",I1,1)-2,2)/60) -> #VALUE! | M1: =VALUE(MID(I1,FIND("'",I1,1)+1,FIND("""",I1,FIND("'",I1,1)+1)-FIND("'",I1,1)-1))/3600 -> #VALUE! | N1: =VALUE(LEFT(J1,2)) -> 0 | O1: =VALUE(MID(J1,FIND("'",J1,1)-2,2)/60) -> #VALUE! | P1: =VALUE(MID(J1,FIND("'",J1,1)+1,FIND("""",J1,FIND("'",J1,1)+1)-FIND("'",J1,1)-1))/3600 -> #VALUE! | Q1: =IF(AND(K1>=42,K1<=50),TRUE,FALSE) -> FALSE | R1: =IFERROR(AND(VALUE(L2)<=59.99999,VALUE(L2)>=0),FALSE) -> FALSE | S1: =IFERROR(AND(VALUE(M2)<=59,VALUE(M2)>=0),FALSE) -> FALSE | T1: =IF(AND(ISNUMBER(I1),K1>41,K1<50),"LAT ok",IF(Q1=FALSE,"grade LAT nok",IF(R1=FALSE,"minute LAT nok",IF(S1=FALSE,"secunde LAT nok","LAT ok")))) -> grade LAT nok | U1: =IF(ISNUMBER(M1+O1)=TRUE,TRUE,IF(AND(NOT(ISNUMBER(M1)),NOT(ISNUMBER(O1))),TRUE,FALSE)) -> TRUE | V1: =IF(AND(ISNUMBER(I1),ISNUMBER(J1)),I1&", "&J1,VALUE(LEFT(K1+L1+M1,6))&", "& VALUE(LEFT(N1+O1+P1,6))) -> 0, 0 | W1: =IF(AND(ISBLANK(I1),ISBLANK(J1)),"",IF(U1,T1&", "&T2,"nu e acelasi mod de completare")) -> grade LAT nok, grade LONG nok | Y1: incident1
A2: Clima- Alunecari de teren, viituri, furtuna, etc… | G2: Alba | L2: =MID(I1,FIND("'",I1,1)-2,2) -> #VALUE! | M2: =MID(I1,FIND("'",I1,1)+1,FIND("""",I1,FIND("'",I1,1)+1)-FIND("'",I1,1)-1) -> #VALUE! | O2: =MID(J1,FIND("'",J1,1)-2,2) -> #VALUE! | P2: =MID(J1,FIND("'",J1,1)+1,FIND("""",J1,FIND("'",J1,1)+1)-FIND("'",J1,1)-1) -> #VALUE! | Q2: =IF(AND(N1>=20, N1<=31),TRUE,FALSE) -> FALSE | R2: =IFERROR(AND(VALUE(O2)<=59,VALUE(O2)>=0),FALSE) -> FALSE | S2: =IFERROR(AND(VALUE(P2)<=59,VALUE(P2)>=0),FALSE) -> FALSE | T2: =IF(AND(ISNUMBER(J1),N1>=20,N1<=31),"LONG ok",IF(Q2=FALSE,"grade LONG nok",IF(R2=FALSE,"minute LONG nok",IF(S2=FALSE,"secunde LONG nok","LONG ok")))) -> grade LONG nok
A3: Defect-Defect cablu/cutie jonctiune, etc,… | G3: Arad
A4: Lucrari infrastructura-Lucrari efectuate de companiile nationale | G4: Arges | I4: ='QAF628'!C38 -> 0 | J4: ='QAF628'!E38 -> 0 | K4: =VALUE(LEFT(I4,2)) -> 0 | L4: =VALUE(MID(I4,FIND("'",I4,1)-2,2)/60) -> #VALUE! | M4: =VALUE(MID(I4,FIND("'",I4,1)+1,FIND("""",I4,FIND("'",I4,1)+1)-FIND("'",I4,1)-1))/3600 -> #VALUE! | N4: =VALUE(LEFT(J4,2)) -> 0 | O4: =VALUE(MID(J4,FIND("'",J4,1)-2,2)/60) -> #VALUE! | P4: =VALUE(MID(J4,FIND("'",J4,1)+1,FIND("""",J4,FIND("'",J4,1)+1)-FIND("'",J4,1)-1))/3600 -> #VALUE! | Q4: =IF(AND(K4>=42,K4<=50),TRUE,FALSE) -> FALSE | R4: =IFERROR(AND(VALUE(L5)<=59,VALUE(L5)>=0),FALSE) -> FALSE | S4: =IFERROR(AND(VALUE(M5)<=59,VALUE(M5)>=0),FALSE) -> FALSE | T4: =IF(AND(ISNUMBER(I4),K4>41,K4<50),"LAT ok",IF(Q4=FALSE,"grade LAT nok",IF(R4=FALSE,"minute LAT nok",IF(S4=FALSE,"secunde LAT nok","LAT ok")))) -> grade LAT nok | U4: =IF(ISNUMBER(M4+O4)=TRUE,TRUE,IF(AND(NOT(ISNUMBER(M4)),NOT(ISNUMBER(O4))),TRUE,FALSE)) -> TRUE | V4: =IF(AND(ISNUMBER(I4),ISNUMBER(J4)),I4&", "&J4,VALUE(LEFT(K4+L4+M4,6))&", "& VALUE(LEFT(N4+O4+P4,6))) -> 0, 0 | W4: =IF(AND(ISBLANK(I4),ISBLANK(J4)),"",IF(U4,T4&", "&T5,"nu e acelasi mod de completare")) -> grade LAT nok, grade LONG nok | Y4: incident2
A5: Lucrari civile-Lucrari efectuate de persoane fizice | G5: Bacau | L5: =MID(I4,FIND("'",I4,1)-2,2) -> #VALUE! | M5: =MID(I4,FIND("'",I4,1)+1,FIND("""",I4,FIND("'",I4,1)+1)-FIND("'",I4,1)-1) -> #VALUE! | O5: =MID(J4,FIND("'",J4,1)-2,2) -> #VALUE! | P5: =MID(J4,FIND("'",J4,1)+1,FIND("""",J4,FIND("'",J4,1)+1)-FIND("'",J4,1)-1) -> #VALUE! | Q5: =IF(AND(N4>=20, N4<=31),TRUE,FALSE) -> FALSE | R5: =IFERROR(AND(VALUE(O5)<=59,VALUE(O5)>=0),FALSE) -> FALSE | S5: =IFERROR(AND(VALUE(P5)<=59,VALUE(P5)>=0),FALSE) -> FALSE | T5: =IF(AND(ISNUMBER(J4),N4>=20,N4<=31),"LONG ok",IF(Q5=FALSE,"grade LONG nok",IF(R5=FALSE,"minute LONG nok",IF(S5=FALSE,"secunde LONG nok","LONG ok")))) -> grade LONG nok
A6: Primarie-Decizii primarie de a taia cablul | G6: Bihor
A7: Demontare infrastructura | G7: Bistrita-Nasaud | I7: ='QAF628'!C41 -> 0 | J7: ='QAF628'!E41 -> 0 | K7: =VALUE(LEFT(I7,2)) -> 0 | L7: =VALUE(MID(I7,FIND("'",I7,1)-2,2)/60) -> #VALUE! | M7: =VALUE(MID(I7,FIND("'",I7,1)+1,FIND("""",I7,FIND("'",I7,1)+1)-FIND("'",I7,1)-1))/3600 -> #VALUE! | N7: =VALUE(LEFT(J7,2)) -> 0 | O7: =VALUE(MID(J7,FIND("'",J7,1)-2,2)/60) -> #VALUE! | P7: =VALUE(MID(J7,FIND("'",J7,1)+1,FIND("""",J7,FIND("'",J7,1)+1)-FIND("'",J7,1)-1))/3600 -> #VALUE! | Q7: =IF(AND(K7>=42,K7<=50),TRUE,FALSE) -> FALSE | R7: =IFERROR(AND(VALUE(L8)<=59,VALUE(L8)>=0),FALSE) -> FALSE | S7: =IFERROR(AND(VALUE(M8)<=59,VALUE(M8)>=0),FALSE) -> FALSE | T7: =IF(AND(ISNUMBER(I7),K7>41,K7<50),"LAT ok",IF(Q7=FALSE,"grade LAT nok",IF(R7=FALSE,"minute LAT nok",IF(S7=FALSE,"secunde LAT nok","LAT ok")))) -> grade LAT nok | U7: =IF(ISNUMBER(M7+O7)=TRUE,TRUE,IF(AND(NOT(ISNUMBER(M7)),NOT(ISNUMBER(O7))),TRUE,FALSE)) -> TRUE | V7: =IF(AND(ISNUMBER(I7),ISNUMBER(J7)),I7&", "&J7,VALUE(LEFT(K7+L7+M7,6))&", "& VALUE(LEFT(N7+O7+P7,6))) -> 0, 0 | W7: =IF(AND(ISBLANK(I7),ISBLANK(J7)),"",IF(U7,T7&", "&T8,"nu e acelasi mod de completare")) -> grade LAT nok, grade LONG nok | Y7: jonctiune 1
A8: Vandalism-Furt | G8: Botosani | L8: =MID(I7,FIND("'",I7,1)-2,2) -> #VALUE! | M8: =MID(I7,FIND("'",I7,1)+1,FIND("""",I7,FIND("'",I7,1)+1)-FIND("'",I7,1)-1) -> #VALUE! | O8: =MID(J7,FIND("'",J7,1)-2,2) -> #VALUE! | P8: =MID(J7,FIND("'",J7,1)+1,FIND("""",J7,FIND("'",J7,1)+1)-FIND("'",J7,1)-1) -> #VALUE! | Q8: =IF(AND(N7>=20, N7<=31),TRUE,FALSE) -> FALSE | R8: =IFERROR(AND(VALUE(O8)<=59,VALUE(O8)>=0),FALSE) -> FALSE | S8: =IFERROR(AND(VALUE(P8)<=59,VALUE(P8)>=0),FALSE) -> FALSE | T8: =IF(AND(ISNUMBER(J7),N7>=20,N7<=31),"LONG ok",IF(Q8=FALSE,"grade LONG nok",IF(R8=FALSE,"minute LONG nok",IF(S8=FALSE,"secunde LONG nok","LONG ok")))) -> grade LONG nok
G9: Braila
C10: EVR | D10: PBM | E10: VHBB | G10: Brasov | I10: ='QAF628'!C42 -> 0 | J10: ='QAF628'!E42 -> 0 | K10: =VALUE(LEFT(I10,2)) -> 0 | L10: =VALUE(MID(I10,FIND("'",I10,1)-2,2)/60) -> #VALUE! | M10: =VALUE(MID(I10,FIND("'",I10,1)+1,FIND("""",I10,FIND("'",I10,1)+1)-FIND("'",I10,1)-1))/3600 -> #VALUE! | N10: =VALUE(LEFT(J10,2)) -> 0 | O10: =VALUE(MID(J10,FIND("'",J10,1)-2,2)/60) -> #VALUE! | P10: =VALUE(MID(J10,FIND("'",J10,1)+1,FIND("""",J10,FIND("'",J10,1)+1)-FIND("'",J10,1)-1))/3600 -> #VALUE! | Q10: =IF(AND(K10>=42,K10<=50),TRUE,FALSE) -> FALSE | R10: =IFERROR(AND(VALUE(L11)<=59,VALUE(L11)>=0),FALSE) -> FALSE | S10: =IFERROR(AND(VALUE(M11)<=59,VALUE(M11)>=0),FALSE) -> FALSE | T10: =IF(AND(ISNUMBER(I10),K10>41,K10<50),"LAT ok",IF(Q10=FALSE,"grade LAT nok",IF(R10=FALSE,"minute LAT nok",IF(S10=FALSE,"secunde LAT nok","LAT ok")))) -> grade LAT nok | U10: =IF(ISNUMBER(M10+O10)=TRUE,TRUE,IF(AND(NOT(ISNUMBER(M10)),NOT(ISNUMBER(O10))),TRUE,FALSE)) -> TRUE | V10: =IF(AND(ISNUMBER(I10),ISNUMBER(J10)),I10&", "&J10,VALUE(LEFT(K10+L10+M10,6))&", "& VALUE(LEFT(N10+O10+P10,6))) -> 0, 0 | W10: =IF(AND(ISBLANK(I10),ISBLANK(J10)),"",IF(U10,T10&", "&T11,"nu e acelasi mod de completare")) -> grade LAT nok, grade LONG nok | Y10: jonctiune 2
A11: FO BB | C11: Y10 | D11: minor | E11: Minor 12h | G11: Bucuresti | L11: =MID(I10,FIND("'",I10,1)-2,2) -> #VALUE! | M11: =MID(I10,FIND("'",I10,1)+1,FIND("""",I10,FIND("'",I10,1)+1)-FIND("'",I10,1)-1) -> #VALUE! | O11: =MID(J10,FIND("'",J10,1)-2,2) -> #VALUE! | P11: =MID(J10,FIND("'",J10,1)+1,FIND("""",J10,FIND("'",J10,1)+1)-FIND("'",J10,1)-1) -> #VALUE! | Q11: =IF(AND(N10>=20, N10<=31),TRUE,FALSE) -> FALSE | R11: =IFERROR(AND(VALUE(O11)<=59,VALUE(O11)>=0),FALSE) -> FALSE | S11: =IFERROR(AND(VALUE(P11)<=59,VALUE(P11)>=0),FALSE) -> FALSE | T11: =IF(AND(ISNUMBER(J10),N10>=20,N10<=31),"LONG ok",IF(Q11=FALSE,"grade LONG nok",IF(R11=FALSE,"minute LONG nok",IF(S11=FALSE,"secunde LONG nok","LONG ok")))) -> grade LONG nok
A12: FO Local | C12: Y8 | D12: Mediu | E12: Major 8h | G12: Buzau
A13: VHBB | C13: Y6 | D13: Major | E13: Critic 4h | G13: Calarasi | I13: ='QAF628'!C43 -> 0 | J13: ='QAF628'!E43 -> 0 | K13: =VALUE(LEFT(I13,2)) -> 0 | L13: =VALUE(MID(I13,FIND("'",I13,1)-2,2)/60) -> #VALUE! | M13: =VALUE(MID(I13,FIND("'",I13,1)+1,FIND("""",I13,FIND("'",I13,1)+1)-FIND("'",I13,1)-1))/3600 -> #VALUE! | N13: =VALUE(LEFT(J13,2)) -> 0 | O13: =VALUE(MID(J13,FIND("'",J13,1)-2,2)/60) -> #VALUE! | P13: =VALUE(MID(J13,FIND("'",J13,1)+1,FIND("""",J13,FIND("'",J13,1)+1)-FIND("'",J13,1)-1))/3600 -> #VALUE! | Q13: =IF(AND(K13>=42,K13<=50),TRUE,FALSE) -> FALSE | R13: =IFERROR(AND(VALUE(L14)<=59,VALUE(L14)>=0),FALSE) -> FALSE | S13: =IFERROR(AND(VALUE(M14)<=59,VALUE(M14)>=0),FALSE) -> FALSE | T13: =IF(AND(ISNUMBER(I13),K13>41,K13<50),"LAT ok",IF(Q13=FALSE,"grade LAT nok",IF(R13=FALSE,"minute LAT nok",IF(S13=FALSE,"secunde LAT nok","LAT ok")))) -> grade LAT nok | U13: =IF(ISNUMBER(M13+O13)=TRUE,TRUE,IF(AND(NOT(ISNUMBER(M13)),NOT(ISNUMBER(O13))),TRUE,FALSE)) -> TRUE | V13: =IF(AND(ISNUMBER(I13),ISNUMBER(J13)),I13&", "&J13,VALUE(LEFT(K13+L13+M13,6))&", "& VALUE(LEFT(N13+O13+P13,6))) -> 0, 0 | W13: =IF(AND(ISBLANK(I13),ISBLANK(J13)),"",IF(U13,T13&", "&T14,"nu e acelasi mod de completare")) -> grade LAT nok, grade LONG nok | Y13: jonctiune 3
G14: Caras-Severin | L14: =MID(I13,FIND("'",I13,1)-2,2) -> #VALUE! | M14: =MID(I13,FIND("'",I13,1)+1,FIND("""",I13,FIND("'",I13,1)+1)-FIND("'",I13,1)-1) -> #VALUE! | O14: =MID(J13,FIND("'",J13,1)-2,2) -> #VALUE! | P14: =MID(J13,FIND("'",J13,1)+1,FIND("""",J13,FIND("'",J13,1)+1)-FIND("'",J13,1)-1) -> #VALUE! | Q14: =IF(AND(N13>=20, N13<=31),TRUE,FALSE) -> FALSE | R14: =IFERROR(AND(VALUE(O14)<=59,VALUE(O14)>=0),FALSE) -> FALSE | S14: =IFERROR(AND(VALUE(P14)<=59,VALUE(P14)>=0),FALSE) -> FALSE | T14: =IF(AND(ISNUMBER(J13),N13>=20,N13<=31),"LONG ok",IF(Q14=FALSE,"grade LONG nok",IF(R14=FALSE,"minute LONG nok",IF(S14=FALSE,"secunde LONG nok","LONG ok")))) -> grade LONG nok
G15: Cluj
A16: Aerian | G16: Constanta | I16: ='QAF628'!C44 -> 0 | J16: ='QAF628'!E44 -> 0 | K16: =VALUE(LEFT(I16,2)) -> 0 | L16: =VALUE(MID(I16,FIND("'",I16,1)-2,2)/60) -> #VALUE! | M16: =VALUE(MID(I16,FIND("'",I16,1)+1,FIND("""",I16,FIND("'",I16,1)+1)-FIND("'",I16,1)-1))/3600 -> #VALUE! | N16: =VALUE(LEFT(J16,2)) -> 0 | O16: =VALUE(MID(J16,FIND("'",J16,1)-2,2)/60) -> #VALUE! | P16: =VALUE(MID(J16,FIND("'",J16,1)+1,FIND("""",J16,FIND("'",J16,1)+1)-FIND("'",J16,1)-1))/3600 -> #VALUE! | Q16: =IF(AND(K16>=42,K16<=50),TRUE,FALSE) -> FALSE | R16: =IFERROR(AND(VALUE(L17)<=59,VALUE(L17)>=0),FALSE) -> FALSE | S16: =IFERROR(AND(VALUE(M17)<=59,VALUE(M17)>=0),FALSE) -> FALSE | T16: =IF(AND(ISNUMBER(I16),K16>42,K16<49),"LAT ok",IF(Q16=FALSE,"grade LAT nok",IF(R16=FALSE,"minute LAT nok",IF(S16=FALSE,"secunde LAT nok","LAT ok")))) -> grade LAT nok | U16: =IF(ISNUMBER(M16+O16)=TRUE,TRUE,IF(AND(NOT(ISNUMBER(M16)),NOT(ISNUMBER(O16))),TRUE,FALSE)) -> TRUE | V16: =IF(AND(ISNUMBER(I16),ISNUMBER(J16)),I16&", "&J16,VALUE(LEFT(K16+L16+M16,6))&", "& VALUE(LEFT(N16+O16+P16,6))) -> 0, 0 | W16: =IF(AND(ISBLANK(I16),ISBLANK(J16)),"",IF(U16,T16&", "&T17,"nu e acelasi mod de completare")) -> grade LAT nok, grade LONG nok | Y16: jonctiune 4
A17: Subteran | G17: Covasna | L17: =MID(I16,FIND("'",I16,1)-2,2) -> #VALUE! | M17: =MID(I16,FIND("'",I16,1)+1,FIND("""",I16,FIND("'",I16,1)+1)-FIND("'",I16,1)-1) -> #VALUE! | O17: =MID(J16,FIND("'",J16,1)-2,2) -> #VALUE! | P17: =MID(J16,FIND("'",J16,1)+1,FIND("""",J16,FIND("'",J16,1)+1)-FIND("'",J16,1)-1) -> #VALUE! | Q17: =IF(AND(N16>=20, N16<=31),TRUE,FALSE) -> FALSE | R17: =IFERROR(AND(VALUE(O17)<=59,VALUE(O17)>=0),FALSE) -> FALSE | S17: =IFERROR(AND(VALUE(P17)<=59,VALUE(P17)>=0),FALSE) -> FALSE | T17: =IF(AND(ISNUMBER(J16),N16>=20,N16<=31),"LONG ok",IF(Q17=FALSE,"grade LONG nok",IF(R17=FALSE,"minute LONG nok",IF(S17=FALSE,"secunde LONG nok","LONG ok")))) -> grade LONG nok
A18: Mixt | G18: Dambovita
G19: Dolj | I19: ='QAF628'!C51 -> 0 | J19: ='QAF628'!E51 -> 0 | K19: =VALUE(LEFT(I19,2)) -> 0 | L19: =VALUE(MID(I19,FIND("'",I19,1)-2,2)/60) -> #VALUE! | M19: =VALUE(MID(I19,FIND("'",I19,1)+1,FIND("""",I19,FIND("'",I19,1)+1)-FIND("'",I19,1)-1))/3600 -> #VALUE! | N19: =VALUE(LEFT(J19,2)) -> 0 | O19: =VALUE(MID(J19,FIND("'",J19,1)-2,2)/60) -> #VALUE! | P19: =VALUE(MID(J19,FIND("'",J19,1)+1,FIND("""",J19,FIND("'",J19,1)+1)-FIND("'",J19,1)-1))/3600 -> #VALUE! | Q19: =IF(AND(K19>=42,K19<=50),TRUE,FALSE) -> FALSE | R19: =IFERROR(AND(VALUE(L20)<=59,VALUE(L20)>=0),FALSE) -> FALSE | S19: =IFERROR(AND(VALUE(M20)<=59,VALUE(M20)>=0),FALSE) -> FALSE | T19: =IF(AND(ISNUMBER(I19),K19>41,K19<50),"LAT ok",IF(Q19=FALSE,"grade LAT nok",IF(R19=FALSE,"minute LAT nok",IF(S19=FALSE,"secunde LAT nok","LAT ok")))) -> grade LAT nok | U19: =IF(ISNUMBER(M19+O19)=TRUE,TRUE,IF(AND(NOT(ISNUMBER(M19)),NOT(ISNUMBER(O19))),TRUE,FALSE)) -> TRUE | V19: =IF(AND(ISNUMBER(I19),ISNUMBER(J19)),I19&", "&J19,VALUE(LEFT(K19+L19+M19,6))&", "& VALUE(LEFT(N19+O19+P19,6))) -> 0, 0 | W19: =IF(AND(ISBLANK(I19),ISBLANK(J19)),"",IF(U19,T19&", "&T20,"nu e acelasi mod de completare")) -> grade LAT nok, grade LONG nok | Y19: camereta 1
G20: Galati | L20: =MID(I19,FIND("'",I19,1)-2,2) -> #VALUE! | M20: =MID(I19,FIND("'",I19,1)+1,FIND("""",I19,FIND("'",I19,1)+1)-FIND("'",I19,1)-1) -> #VALUE! | O20: =MID(J19,FIND("'",J19,1)-2,2) -> #VALUE! | P20: =MID(J19,FIND("'",J19,1)+1,FIND("""",J19,FIND("'",J19,1)+1)-FIND("'",J19,1)-1) -> #VALUE! | Q20: =IF(AND(N19>=20, N19<=31),TRUE,FALSE) -> FALSE | R20: =IFERROR(AND(VALUE(O20)<=59,VALUE(O20)>=0),FALSE) -> FALSE | S20: =IFERROR(AND(VALUE(P20)<=59,VALUE(P20)>=0),FALSE) -> FALSE | T20: =IF(AND(ISNUMBER(J19),N19>=20,N19<=31),"LONG ok",IF(Q20=FALSE,"grade LONG nok",IF(R20=FALSE,"minute LONG nok",IF(S20=FALSE,"secunde LONG nok","LONG ok")))) -> grade LONG nok
A21: aeriana | G21: Giurgiu
A22: subterana | G22: Gorj | I22: ='QAF628'!C52 -> 0 | J22: ='QAF628'!E52 -> 0 | K22: =VALUE(LEFT(I22,2)) -> 0 | L22: =VALUE(MID(I22,FIND("'",I22,1)-2,2)/60) -> #VALUE! | M22: =VALUE(MID(I22,FIND("'",I22,1)+1,FIND("""",I22,FIND("'",I22,1)+1)-FIND("'",I22,1)-1))/3600 -> #VALUE! | N22: =VALUE(LEFT(J22,2)) -> 0 | O22: =VALUE(MID(J22,FIND("'",J22,1)-2,2)/60) -> #VALUE! | P22: =VALUE(MID(J22,FIND("'",J22,1)+1,FIND("""",J22,FIND("'",J22,1)+1)-FIND("'",J22,1)-1))/3600 -> #VALUE! | Q22: =IF(AND(K22>=42,K22<=50),TRUE,FALSE) -> FALSE | R22: =IFERROR(AND(VALUE(L23)<=59,VALUE(L23)>=0),FALSE) -> FALSE | S22: =IFERROR(AND(VALUE(M23)<=59,VALUE(M23)>=0),FALSE) -> FALSE | T22: =IF(AND(ISNUMBER(I22),K22>41,K22<50),"LAT ok",IF(Q22=FALSE,"grade LAT nok",IF(R22=FALSE,"minute LAT nok",IF(S22=FALSE,"secunde LAT nok","LAT ok")))) -> grade LAT nok | U22: =IF(ISNUMBER(M22+O22)=TRUE,TRUE,IF(AND(NOT(ISNUMBER(M22)),NOT(ISNUMBER(O22))),TRUE,FALSE)) -> TRUE | V22: =IF(AND(ISNUMBER(I22),ISNUMBER(J22)),I22&", "&J22,VALUE(LEFT(K22+L22+M22,6))&", "& VALUE(LEFT(N22+O22+P22,6))) -> 0, 0 | W22: =IF(AND(ISBLANK(I22),ISBLANK(J22)),"",IF(U22,T22&", "&T23,"nu e acelasi mod de completare")) -> grade LAT nok, grade LONG nok | Y22: camereta 2
G23: Harghita | L23: =MID(I22,FIND("'",I22,1)-2,2) -> #VALUE! | M23: =MID(I22,FIND("'",I22,1)+1,FIND("""",I22,FIND("'",I22,1)+1)-FIND("'",I22,1)-1) -> #VALUE! | O23: =MID(J22,FIND("'",J22,1)-2,2) -> #VALUE! | P23: =MID(J22,FIND("'",J22,1)+1,FIND("""",J22,FIND("'",J22,1)+1)-FIND("'",J22,1)-1) -> #VALUE! | Q23: =IF(AND(N22>=20, N22<=31),TRUE,FALSE) -> FALSE | R23: =IFERROR(AND(VALUE(O23)<=59,VALUE(O23)>=0),FALSE) -> FALSE | S23: =IFERROR(AND(VALUE(P23)<=59,VALUE(P23)>=0),FALSE) -> FALSE | T23: =IF(AND(ISNUMBER(J22),N22>=20,N22<=31),"LONG ok",IF(Q23=FALSE,"grade LONG nok",IF(R23=FALSE,"minute LONG nok",IF(S23=FALSE,"secunde LONG nok","LONG ok")))) -> grade LONG nok
A24: local | G24: Hunedoara
A25: remote | G25: Ialomita | I25: ='QAF628'!C53 -> 0 | J25: ='QAF628'!E53 -> 0 | K25: =VALUE(LEFT(I25,2)) -> 0 | L25: =VALUE(MID(I25,FIND("'",I25,1)-2,2)/60) -> #VALUE! | M25: =VALUE(MID(I25,FIND("'",I25,1)+1,FIND("""",I25,FIND("'",I25,1)+1)-FIND("'",I25,1)-1))/3600 -> #VALUE! | N25: =VALUE(LEFT(J25,2)) -> 0 | O25: =VALUE(MID(J25,FIND("'",J25,1)-2,2)/60) -> #VALUE! | P25: =VALUE(MID(J25,FIND("'",J25,1)+1,FIND("""",J25,FIND("'",J25,1)+1)-FIND("'",J25,1)-1))/3600 -> #VALUE! | Q25: =IF(AND(K25>=42,K25<=50),TRUE,FALSE) -> FALSE | R25: =IFERROR(AND(VALUE(L26)<=59,VALUE(L26)>=0),FALSE) -> FALSE | S25: =IFERROR(AND(VALUE(M26)<=59,VALUE(M26)>=0),FALSE) -> FALSE | T25: =IF(AND(ISNUMBER(I25),K25>41,K25<50),"LAT ok",IF(Q25=FALSE,"grade LAT nok",IF(R25=FALSE,"minute LAT nok",IF(S25=FALSE,"secunde LAT nok","LAT ok")))) -> grade LAT nok | U25: =IF(ISNUMBER(M25+O25)=TRUE,TRUE,IF(AND(NOT(ISNUMBER(M25)),NOT(ISNUMBER(O25))),TRUE,FALSE)) -> TRUE | V25: =IF(AND(ISNUMBER(I25),ISNUMBER(J25)),I25&", "&J25,VALUE(LEFT(K25+L25+M25,6))&", "& VALUE(LEFT(N25+O25+P25,6))) -> 0, 0 | W25: =IF(AND(ISBLANK(I25),ISBLANK(J25)),"",IF(U25,T25&", "&T26,"nu e acelasi mod de completare")) -> grade LAT nok, grade LONG nok | Y25: camereta 3
G26: Iasi | L26: =MID(I25,FIND("'",I25,1)-2,2) -> #VALUE! | M26: =MID(I25,FIND("'",I25,1)+1,FIND("""",I25,FIND("'",I25,1)+1)-FIND("'",I25,1)-1) -> #VALUE! | O26: =MID(J25,FIND("'",J25,1)-2,2) -> #VALUE! | P26: =MID(J25,FIND("'",J25,1)+1,FIND("""",J25,FIND("'",J25,1)+1)-FIND("'",J25,1)-1) -> #VALUE! | Q26: =IF(AND(N25>=20, N25<=31),TRUE,FALSE) -> FALSE | R26: =IFERROR(AND(VALUE(O26)<=59,VALUE(O26)>=0),FALSE) -> FALSE | S26: =IFERROR(AND(VALUE(P26)<=59,VALUE(P26)>=0),FALSE) -> FALSE | T26: =IF(AND(ISNUMBER(J25),N25>=20,N25<=31),"LONG ok",IF(Q26=FALSE,"grade LONG nok",IF(R26=FALSE,"minute LONG nok",IF(S26=FALSE,"secunde LONG nok","LONG ok")))) -> grade LONG nok
G27: Ilfov
G28: Maramures | I28: ='QAF628'!C54 -> 0 | J28: ='QAF628'!E54 -> 0 | K28: =VALUE(LEFT(I28,2)) -> 0 | L28: =VALUE(MID(I28,FIND("'",I28,1)-2,2)/60) -> #VALUE! | M28: =VALUE(MID(I28,FIND("'",I28,1)+1,FIND("""",I28,FIND("'",I28,1)+1)-FIND("'",I28,1)-1))/3600 -> #VALUE! | N28: =VALUE(LEFT(J28,2)) -> 0 | O28: =VALUE(MID(J28,FIND("'",J28,1)-2,2)/60) -> #VALUE! | P28: =VALUE(MID(J28,FIND("'",J28,1)+1,FIND("""",J28,FIND("'",J28,1)+1)-FIND("'",J28,1)-1))/3600 -> #VALUE! | Q28: =IF(AND(K28>=42,K28<=50),TRUE,FALSE) -> FALSE | R28: =IFERROR(AND(VALUE(L29)<=59,VALUE(L29)>=0),FALSE) -> FALSE | S28: =IFERROR(AND(VALUE(M29)<=59,VALUE(M29)>=0),FALSE) -> FALSE | T28: =IF(AND(ISNUMBER(I28),K28>41,K28<50),"LAT ok",IF(Q28=FALSE,"grade LAT nok",IF(R28=FALSE,"minute LAT nok",IF(S28=FALSE,"secunde LAT nok","LAT ok")))) -> grade LAT nok | U28: =IF(ISNUMBER(M28+O28)=TRUE,TRUE,IF(AND(NOT(ISNUMBER(M28)),NOT(ISNUMBER(O28))),TRUE,FALSE)) -> TRUE | V28: =IF(AND(ISNUMBER(I28),ISNUMBER(J28)),I28&", "&J28,VALUE(LEFT(K28+L28+M28,6))&", "& VALUE(LEFT(N28+O28+P28,6))) -> 0, 0 | W28: =IF(AND(ISBLANK(I28),ISBLANK(J28)),"",IF(U28,T28&", "&T29,"nu e acelasi mod de completare")) -> grade LAT nok, grade LONG nok | Y28: camereta 4
G29: Mehedinti | L29: =MID(I28,FIND("'",I28,1)-2,2) -> #VALUE! | M29: =MID(I28,FIND("'",I28,1)+1,FIND("""",I28,FIND("'",I28,1)+1)-FIND("'",I28,1)-1) -> #VALUE! | O29: =MID(J28,FIND("'",J28,1)-2,2) -> #VALUE! | P29: =MID(J28,FIND("'",J28,1)+1,FIND("""",J28,FIND("'",J28,1)+1)-FIND("'",J28,1)-1) -> #VALUE! | Q29: =IF(AND(N28>=20, N28<=31),TRUE,FALSE) -> FALSE | R29: =IFERROR(AND(VALUE(O29)<=59,VALUE(O29)>=0),FALSE) -> FALSE | S29: =IFERROR(AND(VALUE(P29)<=59,VALUE(P29)>=0),FALSE) -> FALSE | T29: =IF(AND(ISNUMBER(J28),N28>=20,N28<=31),"LONG ok",IF(Q29=FALSE,"grade LONG nok",IF(R29=FALSE,"minute LONG nok",IF(S29=FALSE,"secunde LONG nok","LONG ok")))) -> grade LONG nok
G30: Mures
G31: Neamt
G32: Olt
G33: Prahova
G34: Salaj
G35: Satu Mare
G36: Sibiu
G37: Suceava
G38: Teleorman
G39: Timis
G40: Tulcea
...
